Workbook

Sheet Resumen
A1: ANÁLISIS DE COSTES - OMERIX ERP
A3: Fecha de análisis: | B3: Diciembre 2025
A4: Moneda: | B4: EUR (€)
A6: Concepto | B6: Mínimo (€/mes) | C6: Máximo (€/mes) | D6: Notas
A7: Hosting VPS | B7: =Hosting!B8 -> 7.49 | C7: =Hosting!C8 -> 24.99 | D7: Hostinger KVM recomendado
A8: MongoDB Atlas | B8: =MongoDB!B10 -> 0 | C8: =MongoDB!C10 -> 23 | D8: M0 gratis, M5 para producción
A9: API Claude (IA) | B9: ='API Claude'!E21 -> 1.794 | C9: ='API Claude'!F21 -> 3.588 | D9: Coste por procesamiento albaranes
A10: Almacenamiento (S3/DO) | B10: =Almacenamiento!B19 -> 0 | C10: =Almacenamiento!C19 -> 10 | D10: Para archivos y backups
A11: Dominio + SSL | B11: 1 | C11: 2 | D11: Renovación anual prorrateada
A12: Backup extra | B12: 0 | C12: 5 | D12: Opcional según proveedor
A13: TOTAL INFRAESTRUCTURA | B13: =SUM(B7:B12) -> 10.284 | C13: =SUM(C7:C12) -> 68.578

Sheet Hosting
A1: HOSTING VPS - COMPARATIVA
A3: Proveedor / Plan | B3: Precio (€/mes) | C3: Specs | D3: Notas
A4: Hostinger KVM1 | B4: 7.49 | C4: 1 vCPU, 4GB RAM | D4: Básico para desarrollo
A5: Hostinger KVM2 ⭐ | B5: 12.99 | C5: 2 vCPU, 8GB RAM | D5: RECOMENDADO para producción
A6: Hostinger KVM4 | B6: 24.99 | C6: 4 vCPU, 16GB RAM | D6: Para múltiples clientes
A7: DigitalOcean Droplet | B7: 12 | C7: 2 vCPU, 4GB RAM | D7: Alternativa premium
A8: Rango recomendado: | B8: =MIN(B4:B7) -> 7.49 | C8: =MAX(B4:B7) -> 24.99 | D8: Fácil deploy, puede escalar

Sheet MongoDB
A1: MONGODB ATLAS - PLANES
A3: Plan | B3: Precio (€/mes) | C3: Almacen. | D3: Notas
A4: M0 (Free) | B4: 0 | C4: 512 MB | D4: Desarrollo/testing, sin SLA
A5: M2 (Shared) | B5: 9 | C5: 2 GB | D5: Pequeños proyectos
A6: M5 (Shared) ⭐ | B6: 23 | C6: 5 GB | D6: RECOMENDADO producción básica
A7: M10 (Dedicated) | B7: 50 | C7: 10 GB | D7: Alta disponibilidad
A8: M20 (Dedicated) | B8: 140 | C8: 20 GB | D8: Múltiples clientes
A10: Rango típico: | B10: 0 | C10: 23

Sheet API Claude
A1: COSTES API CLAUDE - PROCESAMIENTO ALBARANES
A3: Modelo: Claude Sonnet 4.5
A4: Precio entrada: $3 / millón tokens
A5: Precio salida: $15 / millón tokens
A6: Descuento Batch API: 50%
A8: Parámetro | B8: Valor | C8: Unidad
A9: Tokens entrada por albarán | B9: 2500 | C9: tokens
A10: Tokens salida por albarán | B10: 800 | C10: tokens
A11: Tipo cambio EUR/USD | B11: 0.92
A13: Coste por albarán (€): | B13: =((B9/1000000)*3 + (B10/1000000)*15)*B11 -> 0.01794
A15: Escenario | B15: Albaranes/mes | C15: Coste (€) | D15: Con Batch -50% | E15: Mínimo | F15: Máximo
A16: Autónomo | B16: 50 | C16: =B16*$B$13 -> 0.897 | D16: =C16*0.5 -> 0.4485 | E16: =D16 -> 0.4485 | F16: =C16 -> 0.897
A17: Pequeño negocio | B17: 200 | C17: =B17*$B$13 -> 3.588 | D17: =C17*0.5 -> 1.794 | E17: =D17 -> 1.794 | F17: =C17 -> 3.588
A18: Mediano | B18: 500 | C18: =B18*$B$13 -> 8.97 | D18: =C18*0.5 -> 4.485 | E18: =D18 -> 4.485 | F18: =C18 -> 8.97
A19: Grande | B19: 1000 | C19: =B19*$B$13 -> 17.94 | D19: =C19*0.5 -> 8.97 | E19: =D19 -> 8.97 | F19: =C19 -> 17.94
A20: Enterprise | B20: 3000 | C20: =B20*$B$13 -> 53.82 | D20: =C20*0.5 -> 26.91 | E20: =D20 -> 26.91 | F20: =C20 -> 53.82
A21: Rango típico (pequeño): | E21: =E17 -> 1.794 | F21: =F17 -> 3.588

Sheet Almacenamiento
A1: ALMACENAMIENTO - DIGITALOCEAN SPACES vs AWS S3
A3: 📦 DIGITALOCEAN SPACES
A4: Concepto | B4: Precio | C4: Incluido | D4: Notas
A5: Plan base | B5: $5/mes | C5: 250 GB + 1 TB transfer | D5: CDN incluido gratis
A6: Almacenamiento extra | B6: $0.02/GiB | C6: - | D6: Sobre los 250 GB
A7: Transferencia extra | B7: $0.01/GiB | C7: - | D7: Sobre 1 TB salida
A8: Inbound (entrada) | B8: GRATIS | C8: Ilimitado | D8: Subir archivos sin coste
A10: ☁️ AWS S3
A11: Clase de almacenamiento | B11: Precio/GB/mes | C11: Uso recomendado | D11: Notas
A12: S3 Standard | B12: $0.023 | C12: Acceso frecuente | D12: Primeros 50 TB
A13: S3 Standard-IA | B13: $0.0125 | C13: Acceso infrecuente | D13: Recuperación rápida
A14: S3 One Zone-IA | B14: $0.01 | C14: Backups secundarios | D14: Sin redundancia multi-zona
A15: S3 Glacier Instant | B15: $0.004 | C15: Archivo con acceso rápido | D15: 68% más barato que IA
A16: Transfer OUT | B16: $0.09/GB | C16: Descarga a internet | D16: Primeros 10 TB
A18: ⭐ RECOMENDACIÓN PARA OMERIX
A19: Rango mensual estimado: | B19: 0 | C19: 10 | D19: Uso típico: 50-100 GB
A21: Para un ERP como Omerix con almacenamiento de:
A22: • Imágenes de albaranes/facturas
A23: • Backups de MongoDB
A24: • Archivos de clientes
A26: ✅ RECOMENDACIÓN: DigitalOcean Spaces
A27: Razones:
A28: 1. Precio fijo predecible ($5/mes incluye 250 GB)
A29: 2. CDN integrado sin coste extra
A30: 3. Compatible S3 (fácil migración)
A31: 4. Transfer generoso (1 TB incluido)
A32: 5. Simplicidad vs complejidad de precios AWS
A34: 📊 CALCULADORA DE COSTES
A35: Tu escenario | B35: Valor | C35: DO Spaces | D35: AWS S3
A36: GB almacenados | B36: 100 | C36: =IF(B36<=250,5,5+(B36-250)*0.02) -> 5 | D36: =B36*0.023 -> 2.3
A37: GB transfer salida/mes | B37: 50 | C37: =IF(B37<=1024,0,(B37-1024)*0.01) -> 0 | D37: =B37*0.09 -> 4.5
A38: TOTAL MENSUAL (€) | C38: =(C36+C37)*0.92 -> 4.6 | D38: =(D36+D37)*0.92 -> 6.256

Sheet Add-ons
A1: MÓDULOS ADD-ON - OMERIX ERP
A3: 🧩 MÓDULOS DISPONIBLES
A4: Módulo | B4: Precio base (€/mes) | C4: Precio variable | D4: Descripción
A5: TPV (Punto de Venta) | B5: 27 | C5: Por cada TPV | D5: Terminal punto de venta táctil, tickets, arqueos
A6: RRHH (Recursos Humanos) | B6: 15 | C6: +1€/empleado (desde 3º) | D6: Nóminas, fichajes, vacaciones, contratos. Incluye 2 empleados
A7: Servicios | B7: 12 | C7: - | D7: Gestión de servicios, SAT, partes de trabajo
A8: Producción | B8: 25 | C8: - | D8: Órdenes fabricación, escandallos, control planta
A9: IA Documentos | B9: 0 | C9: 0.15-0.30€/doc | D9: OCR inteligente albaranes, facturas, pedidos
A10: Usuarios adicionales | B10: 5 | C10: Por usuario | D10: Usuarios extra sobre los incluidos en plan
A11: Multi-empresa | B11: 10 | C11: Por empresa extra | D11: Gestión de empresas adicionales
A12: API Avanzada | B12: 20 | C12: - | D12: Acceso API REST completo, webhooks, integraciones
A13: Backup Premium | B13: 8 | C13: - | D13: Backups cada hora, retención 90 días, restore prioritario
A14: Soporte Prioritario | B14: 15 | C14: - | D14: Respuesta <4h, teléfono directo, formación
A16: 📋 ESTADO DE DESARROLLO
A17: Módulo | B17: Estado | C17: Prioridad | D17: Notas
A18: Core ERP (Ventas, Compras, Stock) | B18: ✅ Implementado | C18: Alta | D18: Funcionalidad base
A19: IA Documentos | B19: ✅ Implementado | C19: Alta | D19: API Claude integrada
A20: Servicios | B20: 🔄 En desarrollo | C20: Alta | D20: Próxima versión
A21: RRHH | B21: 📋 Planificado | C21: Media | D21: Q1 2025
A22: TPV | B22: 📋 Planificado | C22: Media | D22: Q1-Q2 2025
A23: Producción | B23: 📋 Planificado | C23: Baja | D23: Q2 2025
A24: Multi-empresa | B24: 📋 Planificado | C24: Media | D24: Requiere refactor
A27: 🧮 SIMULADOR DE CLIENTE
A28: Concepto | B28: Cantidad | C28: Precio unit. | D28: Subtotal
A29: Plan base (Profesional) | B29: 1 | C29: 59 | D29: =B29*C29 -> 59
A30: TPV adicionales | B30: 2 | C30: 27 | D30: =B30*C30 -> 54
A31: Módulo RRHH | B31: 1 | C31: 19 | D31: =B31*C31 -> 19
A32: Empleados extra RRHH (sobre 2) | B32: 8 | C32: 1 | D32: =B32*C32 -> 8
A33: Módulo Servicios | B33: 1 | C33: 12 | D33: =B33*C33 -> 12
A34: Módulo Producción | B34: 0 | C34: 25 | D34: =B34*C34 -> 0
A35: Usuarios adicionales | B35: 3 | C35: 5 | D35: =B35*C35 -> 15
A36: Docs IA procesados/mes | B36: 150 | C36: 0.25 | D36: =B36*C36 -> 37.5
A37: Soporte Prioritario | B37: 0 | C37: 15 | D37: =B37*C37 -> 0
A39: TOTAL MENSUAL CLIENTE | D39: =SUM(D29:D37) -> 204.5
A40: TOTAL ANUAL | D40: =D39*12 -> 2454
A42: 💰 ANÁLISIS DE MARGEN
A43: Tu coste infraestructura (estimado): | B43: =Resumen!C13 -> 68.578 | C43: €/mes
A44: Coste IA (docs procesados): | B44: =B36*0.015 -> 2.25 | C44: €/mes
A45: Total costes: | B45: =B43+B44 -> 70.828
A46: Ingreso cliente: | B46: =D39 -> 204.5
...

Sheet Simulador ROI
A1: 📊 SIMULADOR ROI - OMERIX ERP
A3: 📋 PRECIOS DE REFERENCIA | E3: 🧩 ADD-ONS
A4: Plan | B4: Precio | C4: Usuarios incl. | E4: Add-on | F4: €/mes
A5: 1-Starter | B5: 29 | C5: 2 | E5: TPV | F5: 27
A6: 2-Profesional | B6: 59 | C6: 5 | E6: RRHH | F6: 15
A7: 3-Business | B7: 99 | C7: 10 | E7: RRHH/empl | F7: 1
A8: 4-Enterprise | B8: 199 | C8: 999 | E8: Servicios | F8: 12
E9: Producción | F9: 25
E10: Usuario+ | F10: 5
E11: Multi-emp | F11: 10
E12: API | F12: 20
E13: Backup+ | F13: 8
E14: Soporte+ | F14: 15
A17: 👥 CARTERA DE CLIENTES
A18: # | B18: Cliente | C18: Plan (1-4) | D18: TPVs | E18: RRHH | F18: Empl+ | G18: Serv | H18: Prod | I18: Usr+ | J18: API | K18: Docs IA | L18: TOTAL €
A19: 1 | B19: Cliente 1 | C19: 2 | D19: 1 | E19: 1 | F19: 5 | G19: 1 | H19: 0 | I19: 2 | J19: 0 | K19: 100 | L19: =IF(C19=0,0,IF(C19=1,$B$5,IF(C19=2,$B$6,IF(C19=3,$B$7,$B$8)))+D19*$F$5+E19*$F$6+F19*$F$7+G19*$F$8+H19*$F$9+I19*$F$10+J19*$F$14+K19*0.2) -> 148
A20: 2 | B20: Cliente 2 | C20: 3 | D20: 3 | E20: 1 | F20: 15 | G20: 1 | H20: 1 | I20: 5 | J20: 1 | K20: 300 | L20: =IF(C20=0,0,IF(C20=1,$B$5,IF(C20=2,$B$6,IF(C20=3,$B$7,$B$8)))+D20*$F$5+E20*$F$6+F20*$F$7+G20*$F$8+H20*$F$9+I20*$F$10+J20*$F$14+K20*0.2) -> 347
A21: 3 | B21: Cliente 3 | C21: 1 | D21: 0 | E21: 0 | F21: 0 | G21: 0 | H21: 0 | I21: 0 | J21: 0 | K21: 20 | L21: =IF(C21=0,0,IF(C21=1,$B$5,IF(C21=2,$B$6,IF(C21=3,$B$7,$B$8)))+D21*$F$5+E21*$F$6+F21*$F$7+G21*$F$8+H21*$F$9+I21*$F$10+J21*$F$14+K21*0.2) -> 33
A22: 4 | C22: 0 | D22: 0 | E22: 0 | F22: 0 | G22: 0 | H22: 0 | I22: 0 | J22: 0 | K22: 0 | L22: =IF(C22=0,0,IF(C22=1,$B$5,IF(C22=2,$B$6,IF(C22=3,$B$7,$B$8)))+D22*$F$5+E22*$F$6+F22*$F$7+G22*$F$8+H22*$F$9+I22*$F$10+J22*$F$14+K22*0.2) -> 0
A23: 5 | C23: 0 | D23: 0 | E23: 0 | F23: 0 | G23: 0 | H23: 0 | I23: 0 | J23: 0 | K23: 0 | L23: =IF(C23=0,0,IF(C23=1,$B$5,IF(C23=2,$B$6,IF(C23=3,$B$7,$B$8)))+D23*$F$5+E23*$F$6+F23*$F$7+G23*$F$8+H23*$F$9+I23*$F$10+J23*$F$14+K23*0.2) -> 0
A24: 6 | C24: 0 | D24: 0 | E24: 0 | F24: 0 | G24: 0 | H24: 0 | I24: 0 | J24: 0 | K24: 0 | L24: =IF(C24=0,0,IF(C24=1,$B$5,IF(C24=2,$B$6,IF(C24=3,$B$7,$B$8)))+D24*$F$5+E24*$F$6+F24*$F$7+G24*$F$8+H24*$F$9+I24*$F$10+J24*$F$14+K24*0.2) -> 0
A25: 7 | C25: 0 | D25: 0 | E25: 0 | F25: 0 | G25: 0 | H25: 0 | I25: 0 | J25: 0 | K25: 0 | L25: =IF(C25=0,0,IF(C25=1,$B$5,IF(C25=2,$B$6,IF(C25=3,$B$7,$B$8)))+D25*$F$5+E25*$F$6+F25*$F$7+G25*$F$8+H25*$F$9+I25*$F$10+J25*$F$14+K25*0.2) -> 0
A26: 8 | C26: 0 | D26: 0 | E26: 0 | F26: 0 | G26: 0 | H26: 0 | I26: 0 | J26: 0 | K26: 0 | L26: =IF(C26=0,0,IF(C26=1,$B$5,IF(C26=2,$B$6,IF(C26=3,$B$7,$B$8)))+D26*$F$5+E26*$F$6+F26*$F$7+G26*$F$8+H26*$F$9+I26*$F$10+J26*$F$14+K26*0.2) -> 0
A27: 9 | C27: 0 | D27: 0 | E27: 0 | F27: 0 | G27: 0 | H27: 0 | I27: 0 | J27: 0 | K27: 0 | L27: =IF(C27=0,0,IF(C27=1,$B$5,IF(C27=2,$B$6,IF(C27=3,$B$7,$B$8)))+D27*$F$5+E27*$F$6+F27*$F$7+G27*$F$8+H27*$F$9+I27*$F$10+J27*$F$14+K27*0.2) -> 0
A28: 10 | C28: 0 | D28: 0 | E28: 0 | F28: 0 | G28: 0 | H28: 0 | I28: 0 | J28: 0 | K28: 0 | L28: =IF(C28=0,0,IF(C28=1,$B$5,IF(C28=2,$B$6,IF(C28=3,$B$7,$B$8)))+D28*$F$5+E28*$F$6+F28*$F$7+G28*$F$8+H28*$F$9+I28*$F$10+J28*$F$14+K28*0.2) -> 0
A29: TOTAL | K29: =SUM(K19:K28) -> 420 | L29: =SUM(L19:L28) -> 528
A32: 💰 ANÁLISIS ROI MENSUAL | E32: 📊 ESTADÍSTICAS
A33: Concepto | B33: Importe € | C33: Notas | E33: Clientes activos: | F33: =COUNTIF(C19:C28,">0") -> 3
A34: Ingresos mensuales | B34: =L29 -> 528 | C34: Suma de todos los clientes | E34: Ticket medio: | F34: =IF(F33>0,L29/F33,0) -> 176
A35: Coste infraestructura | B35: =Resumen!C13 -> 68.578 | C35: Hosting + MongoDB + Storage | E35: Docs IA totales/mes: | F35: =K29 -> 420
A36: Coste IA (docs procesados) | B36: =K29*0.015 -> 6.3 | C36: Tu coste real API Claude | E36: Ingreso por IA: | F36: =K29*0.2 -> 84
A37: Otros costes fijos | B37: 50 | C37: Dominio, email, herramientas... | E37: Margen IA: | F37: =F36-(K29*0.015) -> 77.7
A38: TOTAL COSTES | B38: =SUM(B35:B37) -> 124.878
A39: BENEFICIO BRUTO MENSUAL | B39: =B34-B38 -> 403.122 | E39: Clientes Starter: | F39: =COUNTIF(C19:C28,1) -> 1
A40: Margen bruto % | B40: =IF(B34>0,B39/B34,0) -> 0.76348864 | E40: Clientes Profesional: | F40: =COUNTIF(C19:C28,2) -> 1
E41: Clientes Business: | F41: =COUNTIF(C19:C28,3) -> 1
A42: 📈 PROYECCIÓN ANUAL | E42: Clientes Enterprise: | F42: =COUNTIF(C19:C28,4) -> 0
A43: Ingresos anuales | B43: =B34*12 -> 6336
A44: Costes anuales | B44: =B38*12 -> 1498.536
A45: BENEFICIO ANUAL | B45: =B43-B44 -> 4837.464
...

Sheet Precios SaaS
A1: MODELO DE PRECIOS SAAS - OMERIX
A3: Plan | B3: Usuarios | C3: Precio (€/mes) | D3: Características
A4: Starter | B4: 1-2 | C4: 29 | D4: Módulos básicos, 1 empresa
A5: Profesional | B5: 3-5 | C5: 59 | D5: + Informes avanzados, soporte email
A6: Business | B6: 6-10 | C6: 99 | D6: + Multi-empresa, API, prioridad
A7: Enterprise | B7: Ilimitados | C7: 199 | D7: + Personalización, SLA, soporte 24/7
A10: 💡 MÓDULO IA (Pay-per-use)
A11: Volumen docs/mes | B11: Precio/doc (€) | C11: Tu coste | D11: Tu margen
A12: 1-50 | B12: 0.3 | C12: =0.015 -> 0.015 | D12: =1-(C12/B12) -> 0.95
A13: 51-200 | B13: 0.25 | C13: =0.015 -> 0.015 | D13: =1-(C13/B13) -> 0.94
A14: 201-500 | B14: 0.2 | C14: =0.015 -> 0.015 | D14: =1-(C14/B14) -> 0.925
A15: 501-1000 | B15: 0.15 | C15: =0.015 -> 0.015 | D15: =1-(C15/B15) -> 0.9
A16: +1000 | B16: 0.12 | C16: =0.015 -> 0.015 | D16: =1-(C16/B16) -> 0.875
A19: 📈 ANÁLISIS ROI
A20: Inversión desarrollo (estimada): | B20: 8000 | C20: €
A21: Clientes plan Profesional: | B21: 10
A22: Ingresos mensuales: | B22: =B21*59 -> 590
A23: Costes mensuales infra: | B23: =Resumen!C13 -> 68.578
A24: Beneficio mensual: | B24: =B22-B23 -> 521.422
A25: Meses para break-even: | B25: =ROUND(B20/B24,1) -> 15.3
